<?xml version="1.0" ?>
<!-- =================================================================================== -->
<!-- |    This document was autogenerated by xacro from hexapod_leg.xacro              | -->
<!-- |    EDITING THIS FILE BY HAND IS NOT RECOMMENDED                                 | -->
<!-- =================================================================================== -->
<robot name="hexapod" xmlns:xacro="http://ros.org/wiki/xacro">
  <!-- Build the body frame -->
  <link name="base_link"/>
  <joint name="base_joint" type="fixed">
    <parent link="base_link"/>
    <child link="thorax"/>
    <origin rpy="0 0 0" xyz="0 0 0"/>
  </joint>
  <link name="thorax">
    <visual>
      <origin rpy="0 0 0" xyz="0 0 0"/>
      <geometry>
        <mesh filename="package://hexapod_description/meshes/thorax.STL"/>
      </geometry>
      <material name="grey">
        <color rgba="0.5 0.5 0.5 1"/>
      </material>
    </visual>
  </link>
  <!-- Pi parameter -->
  <!-- <xacro:property name="pi" value="3.1415926535897931" /> -->
  <!-- Build leg -->
  <joint name="leg_center_joint_r1" type="fixed">
    <origin rpy="0 0 0" xyz="0.087598 -0.050575 0"/>
    <!-- xyz="0.087598 -0.050575 0" -->
    <parent link="thorax"/>
    <child link="leg_center_r1"/>
  </joint>
  <link name="leg_center_r1"/>
  <joint name="coxa_joint_r1" type="revolute">
    <origin rpy="0 0 -1.05" xyz="0 0 0"/>
    <parent link="leg_center_r1"/>
    <child link="coxa_r1"/>
    <axis xyz="0 0 -1"/>
    <limit effort="10000" lower="-1.57079632679" upper="1.57079632679" velocity="100"/>
  </joint>
  <link name="coxa_r1">
    <visual>
      <origin rpy="0 0 0" xyz="0 0 0"/>
      <geometry>
        <mesh filename="package://hexapod_description/meshes/coxa_r.STL"/>
      </geometry>
      <material name="">
        <color rgba="0.7 0.7 0 1"/>
      </material>
    </visual>
  </link>
  <joint name="femur_joint_r1" type="revolute">
    <origin rpy="-1.5708 0 0" xyz="0.0294 0 0"/>
    <parent link="coxa_r1"/>
    <child link="femur_r1"/>
    <axis xyz="0 0 -1"/>
    <limit effort="10000" lower="-1.57079632679" upper="1.57079632679" velocity="100"/>
  </joint>
  <link name="femur_r1">
    <visual>
      <origin rpy="0 0 0" xyz="0 0 0"/>
      <geometry>
        <mesh filename="package://hexapod_description/meshes/femur_r.STL"/>
      </geometry>
      <material name="">
        <color rgba="0 0.7 0.7 1"/>
      </material>
    </visual>
  </link>
  <joint name="tibia_joint_r1" type="revolute">
    <origin rpy="3.1416 0 1.57" xyz="0.08 0 0"/>
    <parent link="femur_r1"/>
    <child link="tibia_r1"/>
    <axis xyz="0 0 1"/>
    <limit effort="10000" lower="-1.57079632679" upper="1.57079632679" velocity="100"/>
  </joint>
  <link name="tibia_r1">
    <visual>
      <origin rpy="0 0 0.06" xyz="0 0 0"/>
      <geometry>
        <mesh filename="package://hexapod_description/meshes/tibia_r.STL"/>
      </geometry>
      <material name="">
        <color rgba="0.7 0 0.7 1"/>
      </material>
    </visual>
  </link>
  <joint name="tibia_foot_joint_r1" type="fixed">
    <origin rpy="0 0 0" xyz="0.11145 0 0"/>
    <parent link="tibia_r1"/>
    <child link="tibia_foot_r1"/>
  </joint>
  <link name="tibia_foot_r1"/>
</robot>

